Workbook

Sheet Summary
A1: Allied fleet status at start of 25 Dec 1941 (from wpae021 incoming file, game date 12/25/41)
A2: Counts below are live formulas over the Active Ships, Task Forces, Reinforcements and Losses tabs.
A4: Active Allied ships | B4: =COUNTA('Active Ships'!A2:A1289) -> 1288
A5: at sea in task forces | B5: =COUNTIF('Active Ships'!F2:F1289,">=0") -> 913
A6: in port | B6: =COUNTIF('Active Ships'!E2:E1289,"In port*") -> 375
A7: Allied task forces | B7: =COUNTA('Task Forces'!A2:A252) -> 251
A8: Damaged ships (any sys/float/engine damage) | B8: =COUNTA('Damaged Ships'!A2:A577) -> 576
A9: Ships on fire | B9: =COUNTIF('Active Ships'!S2:S1289,">0") -> 2
A10: Ships below 25% fuel | B10: =COUNTIFS('Active Ships'!K2:K1289,"<0.25",'Active Ships'!J2:J1289,">0") -> 34
A11: Ships lost (in these saves) | B11: =COUNTA(Losses!A2:A94) -> 93
A12: Future reinforcements scheduled | B12: =COUNTA(Reinforcements!A2:A5734) -> 5733
A15: Active ships by type | D15: Active ships by nation
A16: xAK | B16: =COUNTIF('Active Ships'!B2:B1289,A16) -> 269 | D16: USA | E16: =COUNTIF('Active Ships'!D2:D1289,D16) -> 578
A17: xAP | B17: =COUNTIF('Active Ships'!B2:B1289,A17) -> 150 | D17: UK | E17: =COUNTIF('Active Ships'!D2:D1289,D17) -> 276
A18: xAKL | B18: =COUNTIF('Active Ships'!B2:B1289,A18) -> 126 | D18: Netherlands | E18: =COUNTIF('Active Ships'!D2:D1289,D18) -> 169
A19: AG | B19: =COUNTIF('Active Ships'!B2:B1289,A19) -> 77 | D19: Australia | E19: =COUNTIF('Active Ships'!D2:D1289,D19) -> 123
A20: DD | B20: =COUNTIF('Active Ships'!B2:B1289,A20) -> 77 | D20: Other Allied | E20: =COUNTIF('Active Ships'!D2:D1289,D20) -> 61
A21: TK | B21: =COUNTIF('Active Ships'!B2:B1289,A21) -> 71 | D21: India | E21: =COUNTIF('Active Ships'!D2:D1289,D21) -> 23
A22: SS | B22: =COUNTIF('Active Ships'!B2:B1289,A22) -> 69 | D22: Philippines | E22: =COUNTIF('Active Ships'!D2:D1289,D22) -> 21
A23: AMc | B23: =COUNTIF('Active Ships'!B2:B1289,A23) -> 74 | D23: New Zealand | E23: =COUNTIF('Active Ships'!D2:D1289,D23) -> 17
A24: PT | B24: =COUNTIF('Active Ships'!B2:B1289,A24) -> 44 | D24: Canada | E24: =COUNTIF('Active Ships'!D2:D1289,D24) -> 14
A25: AVP | B25: =COUNTIF('Active Ships'!B2:B1289,A25) -> 27 | D25: Free French | E25: =COUNTIF('Active Ships'!D2:D1289,D25) -> 6
A26: AM | B26: =COUNTIF('Active Ships'!B2:B1289,A26) -> 26
A27: APD | B27: =COUNTIF('Active Ships'!B2:B1289,A27) -> 22
A28: CL | B28: =COUNTIF('Active Ships'!B2:B1289,A28) -> 21
A29: AO | B29: =COUNTIF('Active Ships'!B2:B1289,A29) -> 21
A30: CA | B30: =COUNTIF('Active Ships'!B2:B1289,A30) -> 17
A31: AP | B31: =COUNTIF('Active Ships'!B2:B1289,A31) -> 15
A32: KV | B32: =COUNTIF('Active Ships'!B2:B1289,A32) -> 15
A33: PG | B33: =COUNTIF('Active Ships'!B2:B1289,A33) -> 14
A34: AKE | B34: =COUNTIF('Active Ships'!B2:B1289,A34) -> 13
A35: DMS | B35: =COUNTIF('Active Ships'!B2:B1289,A35) -> 13
A36: YP | B36: =COUNTIF('Active Ships'!B2:B1289,A36) -> 10
A37: BB | B37: =COUNTIF('Active Ships'!B2:B1289,A37) -> 10
A38: ACM | B38: =COUNTIF('Active Ships'!B2:B1289,A38) -> 10
A39: PC | B39: =COUNTIF('Active Ships'!B2:B1289,A39) -> 10
A40: AMC | B40: =COUNTIF('Active Ships'!B2:B1289,A40) -> 74
A41: HDML | B41: =COUNTIF('Active Ships'!B2:B1289,A41) -> 9
A42: AS | B42: =COUNTIF('Active Ships'!B2:B1289,A42) -> 9
A43: CM | B43: =COUNTIF('Active Ships'!B2:B1289,A43) -> 8
...

Sheet Active Ships
A1: Ship | B1: Type | C1: Class | D1: Nation | E1: Location | F1: TF | G1: Captain | H1: Crew exp | I1: Fuel | J1: Max fuel | K1: Fuel % | L1: Endurance (nm) | M1: Max speed (kn) | N1: Sys dmg | O1: Float dmg | P1: Float major | Q1: Eng dmg | R1: Eng major | S1: Fire
A2: British Motorist | B2: TK | C2: Federal Type-E | D2: UK | E2: At sea, TF 18 (48,128) | F2: 18 | G2: Campbell G. | H2: 25 | I2: 1240 | J2: 1321 | K2: 0.93868282 | L2: 11264 | M2: 14 | N2: 5 | O2: 0 | P2: 0 | Q2: 1 | R2: 1 | S2: 0
A3: Bengalen | B3: xAK | C3: Euro K Cargo | D3: Netherlands | E3: At sea, TF 18 (48,128) | F3: 18 | G3: Blokzijl V. | H3: 19 | I3: 1309 | J3: 1366 | K3: 0.95827233 | L3: 17153 | M3: 14 | N3: 1 | O3: 0 | P3: 0 | Q3: 1 | R3: 1 | S3: 0
A4: La Cordillera | B4: xAK | C4: Euro M Cargo | D4: UK | E4: At sea, TF 18 (48,128) | F4: 18 | G4: Webster D. | H4: 15 | I4: 1212 | J4: 1288 | K4: 0.94099379 | L4: 11574 | M4: 14 | N4: 0 | O4: 0 | P4: 0 | Q4: 0 | R4: 0 | S4: 0
A5: Hong Peng | B5: xAP | C5: Straits/Hong | D5: UK | E5: At sea, TF 18 (48,128) | F5: 18 | G5: Goodwin W. | H5: 15 | I5: 835 | J5: 930 | K5: 0.89784946 | L5: 7003 | M5: 14 | N5: 0 | O5: 0 | P5: 0 | Q5: 0 | R5: 0 | S5: 0
A6: Skipjack | B6: SS | C6: Salmon | D6: USA | E6: At sea, TF 197 (79,88) Cagayan | F6: 197 | G6: Freeman, C.L. | H6: 55 | I6: 260 | J6: 314 | K6: 0.82802548 | L6: 9108 | M6: 21 | N6: 0 | O6: 0 | P6: 0 | Q6: 0 | R6: 0 | S6: 0
A7: Anniston City | B7: xAK | C7: Hog Island Cargo | D7: USA | E7: At sea, TF 199 (226,83) near San Diego | F7: 199 | G7: Allison N. | H7: 15 | I7: 934 | J7: 1440 | K7: 0.64861111 | L7: 9534 | M7: 12 | N7: 0 | O7: 0 | P7: 0 | Q7: 0 | R7: 0 | S7: 0
A8: Dewey | B8: DD | C8: Farragut | D8: USA | E8: At sea, TF 201 (209,92) | F8: 201 | G8: Chillingworth, C. | H8: 55 | I8: 476 | J8: 600 | K8: 0.79333333 | L8: 4561 | M8: 32 | N8: 1 | O8: 0 | P8: 0 | Q8: 0 | R8: 0 | S8: 0
A9: MacDonough | B9: DD | C9: Farragut | D9: USA | E9: At sea, TF 201 (209,92) | F9: 201 | G9: Dennett, E. | H9: 59 | I9: 478 | J9: 600 | K9: 0.79666667 | L9: 4580 | M9: 32 | N9: 1 | O9: 0 | P9: 0 | Q9: 0 | R9: 0 | S9: 0
A10: Phelps | B10: DD | C10: Porter | D10: USA | E10: At sea, TF 201 (209,92) | F10: 201 | G10: Beck, E. | H10: 58 | I10: 534 | J10: 635 | K10: 0.84094488 | L10: 6307 | M10: 34 | N10: 1 | O10: 0 | P10: 0 | Q10: 1 | R10: 1 | S10: 0
A11: Shaw | B11: DD | C11: Mahan | D11: USA | E11: At sea, TF 201 (209,92) | F11: 201 | G11: Jones, W. | H11: 61 | I11: 421 | J11: 522 | K11: 0.80651341 | L11: 5242 | M11: 35 | N11: 4 | O11: 0 | P11: 0 | Q11: 0 | R11: 0 | S11: 0
A12: Salmon | B12: SS | C12: Salmon | D12: USA | E12: At sea, TF 203 (72,90) Tawi Tawi | F12: 203 | G12: McKinney, E.B. | H12: 55 | I12: 247 | J12: 314 | K12: 0.7866242 | L12: 8652 | M12: 21 | N12: 0 | O12: 0 | P12: 0 | Q12: 0 | R12: 0 | S12: 0
A13: Seal | B13: SS | C13: Salmon | D13: USA | E13: At sea, TF 203 (72,90) Tawi Tawi | F13: 203 | G13: Hurd, K.C. | H13: 55 | I13: 247 | J13: 314 | K13: 0.7866242 | L13: 8652 | M13: 21 | N13: 1 | O13: 0 | P13: 0 | Q13: 0 | R13: 0 | S13: 0
... A914: Malda | B914: xAP | C914: Tasman/India | D914: UK | E914: At sea, TF 98 (30,34) | F914: 98 | G914: Galbraith B. | H914: 11 | I914: 1272 | J914: 1272 | K914: 1 | L914: 9700 | M914: 15 | N914: 0 | O914: 0 | P914: 0 | Q914: 0 | R914: 0 | S914: 0
A915: Vito | B915: xAK | C915: Euro M Cargo | D915: Other Allied | E915: In port: (104,195) | G915: Edge J. | H915: 20 | I915: 1288 | J915: 1288 | K915: 1 | L915: 12300 | M915: 14 | N915: 0 | O915: 0 | P915: 0 | Q915: 0 | R915: 0 | S915: 0
A916: Cosgrove | B916: AMc | C916: Castle Trawler | D916: New Zealand | E916: In port: (108,193) | G916: Burgess R. | H916: 15 | I916: 97 | J916: 97 | K916: 1 | L916: 1600 | M916: 11 | N916: 0 | O916: 0 | P916: 0 | Q916: 0 | R916: 0 | S916: 0
A917: Currell | B917: AMc | C917: Castle Trawler | D917: New Zealand | E917: In port: (108,193) | G917: Thompson R. | H917: 13 | I917: 97 | J917: 97 | K917: 1 | L917: 1600 | M917: 11 | N917: 0 | O917: 0 | P917: 0 | Q917: 0 | R917: 0 | S917: 0
A918: Arizonan | B918: AG | C918: Transmarine Tender | D918: USA | E918: In port: (112,191) | G918: Brinkley, N.S. | H918: 10 | I918: 1010 | J918: 1010 | K918: 1 | L918: 11000 | M918: 12 | N918: 1 | O918: 0 | P918: 0 | Q918: 0 | R918: 0 | S918: 0
A919: Atlanta City | B919: AG | C919: Isthmian Tender | D919: USA | E919: In port: (112,191) | G919: Shedlock, V.D. | H919: 11 | I919: 1320 | J919: 1320 | K919: 1 | L919: 13600 | M919: 12 | N919: 1 | O919: 0 | P919: 0 | Q919: 0 | R919: 0 | S919: 0
A920: Dakotan | B920: AG | C920: Isthmian Tender | D920: USA | E920: In port: (112,191) | G920: Boyles, E.V. | H920: 8 | I920: 1320 | J920: 1320 | K920: 1 | L920: 13600 | M920: 12 | N920: 1 | O920: 0 | P920: 0 | Q920: 0 | R920: 0 | S920: 0
A921: Puerto Rican | B921: AG | C921: Transmarine Tender | D921: USA | E921: In port: (112,191) | G921: Ruby, G.I. | H921: 4 | I921: 1010 | J921: 1010 | K921: 1 | L921: 11000 | M921: 12 | N921: 1 | O921: 0 | P921: 0 | Q921: 0 | R921: 0 | S921: 0
A922: Santa Rita | B922: AG | C922: Isthmian Tender | D922: USA | E922: In port: (112,191) | G922: Proffit, K.N. | H922: 5 | I922: 1320 | J922: 1320 | K922: 1 | L922: 13600 | M922: 12 | N922: 1 | O922: 0 | P922: 0 | Q922: 0 | R922: 0 | S922: 0
A923: Swan | B923: AVP | C923: Bird AVP | D923: USA | E923: In port: (113,140) | G923: Vaughn U. | H923: 18 | I923: 143 | J923: 200 | K923: 0.715 | L923: 4647 | M923: 14 | N923: 0 | O923: 0 | P923: 0 | Q923: 0 | R923: 0 | S923: 0
A924: Gale | B924: AMc | C924: Castle Trawler | D924: New Zealand | E924: In port: (132,160) | G924: Baker U. | H924: 15 | I924: 97 | J924: 97 | K924: 1 | L924: 1600 | M924: 11 | N924: 0 | O924: 0 | P924: 0 | Q924: 0 | R924: 0 | S924: 0
A925: Kingfisher | B925: AVP | C925: Bird AVP | D925: USA | E925: In port: (148,161) | G925: Wedemeyer, A.S. | H925: 32 | I925: 200 | J925: 200 | K925: 1 | L925: 6500 | M925: 14 | N925: 1 | O925: 0 | P925: 0 | Q925: 0 | R925: 0 | S925: 0
A926: Robin | B926: AM | C926: Bird | D926: USA | E926: In port: (164,112) | G926: Van Voorhis, H.V. | H926: 31 | I926: 200 | J926: 200 | K926: 1 | L926: 6500 | M926: 14 | N926: 0 | O926: 0 | P926: 0 | Q926: 0 | R926: 0 | S926: 0
... A1289: Niagara | B1289: AGP | C1289: Niagara | D1289: USA | E1289: In port: near Tulagi (114,138) | G1289: Dragoon, M.W. | H1289: 16 | I1289: 69 | J1289: 500 | K1289: 0.138 | L1289: 828 | M1289: 12 | N1289: 0 | O1289: 0 | P1289: 0 | Q1289: 0 | R1289: 0 | S1289: 0

Sheet Task Forces
A1: TF | B1: Mission | C1: Current hex / place | D1: Home port | E1: Destination | F1: Next hexes on path | G1: Ships | H1: Flagship | I1: Lowest fuel % | J1: Damaged ships | K1: Ship list
A2: 18 | B2: Transport (CS convoy) | C2: (48,128) | D2: Soerabaja (56,104) | E2: Soerabaja (56,104) | F2: 48,127 > 48,126 > 48,125 > 49,124 > 49,123 | G2: 4 | H2: TK British Motorist | I2: 0.9 | J2: 2 | K2: xAK La Cordillera, xAP Hong Peng, xAK Bengalen, TK British Motorist
A3: 43 | B3: Cargo (?) | C3: (58,117) | D3: Soerabaja (56,104) | E3: Broome (62,127) | F3: 59,118 > 58,119 > 59,120 > 59,121 > 60,122 | G3: 1 | H3: xAKL Shinai | I3: 0.44 | J3: 1 | K3: xAKL Shinai
A4: 98 | B4: Escort (?) | C4: (30,34) | D4: near Madurai (28,40) | F4: 29,35 > 29,36 > 28,37 > 28,38 > 27,39 | G4: 4 | H4: xAP Doumer | I4: 1 | J4: 0 | K4: xAP Doumer, xAP Malda, AMc Poona, AMc Madura
A5: 197 | B5: Submarine | C5: (79,88) Cagayan | D5: Darwin (76,124) | F5: 80,88 > 80,88 > 80,88 > 80,88 > 80,88 | G5: 1 | H5: SS Skipjack | I5: 0.83 | J5: 0 | K5: SS Skipjack
A6: 199 | B6: Transport | C6: (226,83) near San Diego | D6: San Diego (227,78) | E6: San Diego (227,78) | F6: 227,82 > 226,81 > 227,80 > 226,79 > 227,78 | G6: 1 | H6: xAK Anniston City | I6: 0.65 | J6: 0 | K6: xAK Anniston City
A7: 201 | B7: ASW Combat | C7: (209,92) | D7: San Diego (227,78) | E7: San Diego (227,78) | F7: 210,92 > 210,91 > 211,91 > 212,90 > 213,90 | G7: 4 | H7: DD Phelps | I7: 0.79 | J7: 4 | K7: DD Shaw, DD Phelps, DD Dewey, DD MacDonough
A8: 203 | B8: Submarine | C8: (72,90) Tawi Tawi | D8: Darwin (76,124) | F8: 71,89 > 71,89 > 71,89 > 71,89 > 70,93 | G8: 3 | H8: SS Sturgeon | I8: 0.79 | J8: 2 | K8: SS Salmon, SS Seal, SS Sturgeon
A9: 210 | B9: Troop transport (?) | C9: (65,106) Makassar | D9: near Denpasar (59,109) | E9: near Denpasar (59,109) | F9: 64,107 > 63,107 > 63,108 > 62,108 > 61,108 | G9: 2 | H9: xAKL Schouten | I9: 0.77 | J9: 0 | K9: xAKL Schouten, xAKL Sipirok
A10: 216 | B10: Troop transport (?) | C10: (58,111) near Denpasar | D10: Soerabaja (56,104) | E10: Broome (62,127) | F10: 59,112 > 58,113 > 59,114 > 58,115 > 59,116 | G10: 3 | H10: xAK Empire Hamble | I10: 0.71 | J10: 0 | K10: xAK Empire Hamble, xAK Gorgon, xAK Lowana
A11: 218 | B11: Troop transport (?) | C11: (9,13) | D11: Abadan (39,3) | E11: (11,62) | F11: 10,14 > 9,15 > 10,16 > 9,17 > 10,18 | G11: 1 | H11: xAP Tairea | I11: 0.82 | J11: 0 | K11: xAP Tairea
A12: 219 | B12: Escort (?) | C12: (45,106) | D12: Colombo (29,48) | E12: Colombo (29,48) | F12: 44,106 > 43,106 > 42,106 > 41,106 > 40,106 | G12: 4 | H12: BC Repulse | I12: 0.78 | J12: 1 | K12: BC Repulse, DD Stronghold, DD Thracian, DD Jupiter
A13: 220 | B13: Transport | C13: (226,107) | D13: Pearl Harbor (180,107) | E13: Pearl Harbor (180,107) | F13: 225,107 > 224,107 > 223,107 > 222,107 > 221,107 | G13: 1 | H13: xAK Wilhelmina | I13: 0.98 | J13: 0 | K13: xAK Wilhelmina
A14: 222 | B14: Troop transport (?) | C14: (61,106) | D14: Makassar (65,106) | E14: Makassar (65,106) | F14: 62,106 > 63,106 > 64,106 > 65,106 > 61,106 | G14: 3 | H14: xAP Siberg | I14: 0.95 | J14: 0 | K14: xAP Rochussen, xAP Rooseboom, xAP Siberg
A15: 223 | B15: Troop transport (?) | C15: (72,121) near Darwin | D15: Soerabaja (56,104) | E15: Soerabaja (56,104) | F15: 72,120 > 71,120 > 70,119 > 69,119 > 69,118 | G15: 9 | H15: AM Ballarat | I15: 0.83 | J15: 8 | K15: AM Ballarat, xAP Glenorchy, xAP Kota Radja, xAP Kota Pinang, xAP Tjisaroea, xAKL Patris, xAK Tjikandi, xAK Tjikarang, xAP Van Overstraten
A16: 225 | B16: Transport | C16: (5,51) | D16: Cape Town (2,67) | E16: Cape Town (2,67) | F16: 4,51 > 4,51 > 4,51 > 4,51 > 4,51 | G16: 3 | H16: xAK Howra | I16: 0.56 | J16: 0 | K16: xAK Steel Maker, xAK Erinpura, xAK Howra
A17: 226 | B17: Transport | C17: (226,107) | D17: Pearl Harbor (180,107) | E17: Pearl Harbor (180,107) | F17: 225,107 > 224,107 > 223,107 > 222,107 > 221,107 | G17: 1 | H17: xAK Maliko | I17: 1 | J17: 0 | K17: xAK Maliko
A18: 230 | B18: Escort (?) | C18: (216,70) near San Francisco | D18: Alameda (219,70) | E18: Alameda (219,70) | F18: 217,70 > 218,70 > 219,70 > 214,70 > 215,70 | G18: 4 | H18: BB Oklahoma | I18: 0.51 | J18: 4 | K18: BB Nevada, BB Oklahoma, DD Helm, DD Patterson
A19: 232 | B19: Transport | C19: (57,113) | D19: (49,141) | E19: (49,141) | F19: 57,114 > 56,115 > 56,116 > 55,117 > 55,118 | G19: 1 | H19: xAKL Princess of Negros | I19: 0.91 | J19: 0 | K19: xAKL Princess of Negros
A20: 233 | B20: Troop transport (?) | C20: (56,104) Soerabaja | D20: Soerabaja (56,104) | E20: (57,129) | F20: 56,105 > 57,105 > 58,106 > 57,107 > 57,108 | G20: 2 | H20: xAP Kota Gede | I20: 0.45 | J20: 0 | K20: xAP Kota Gede, xAP Speelman
A21: 234 | B21: Submarine | C21: (99,121) | D21: Sydney (90,167) | E21: Sydney (90,167) | F21: 100,122 > 100,123 > 101,124 > 100,125 > 101,126 | G21: 1 | H21: SS Tarpon | I21: 0.65 | J21: 1 | K21: SS Tarpon
A22: 235 | B22: Submarine | C22: (80,94) near Davao | D22: Darwin (76,124) | F22: 79,94 > 79,94 > 79,94 > 80,95 > 80,95 | G22: 1 | H22: SS S-40 | I22: 0.51 | J22: 0 | K22: SS S-40
A23: 237 | B23: Transport | C23: (188,120) | D23: Pearl Harbor (180,107) | F23: 189,120 > 189,119 > 190,119 > 191,118 > 192,118 | G23: 1 | H23: AO Brazos | I23: 0.98 | J23: 1 | K23: AO Brazos
A24: 239 | B24: Transport (CS convoy) | C24: (226,83) near San Diego | D24: San Diego (227,78) | E24: San Diego (227,78) | F24: 227,82 > 226,81 > 227,80 > 226,79 > 227,78 | G24: 4 | H24: xAK Makua | I24: 0.95 | J24: 0 | K24: xAK Liloa, xAK Mahimahi, xAK Makua, xAK Mana
A25: 240 | B25: Submarine | C25: (84,89) near Siargao | D25: Darwin (76,124) | F25: 84,90 > 84,90 > 84,90 > 84,90 > 85,86 | G25: 1 | H25: SS Spearfish | I25: 0.83 | J25: 1 | K25: SS Spearfish
A26: 242 | B26: Surface Combat | C26: (139,170) | D26: Sydney (90,167) | E26: Sydney (90,167) | F26: 138,170 > 137,169 > 137,168 > 136,168 > 135,168 | G26: 1 | H26: CL Trenton | I26: 0.34 | J26: 1 | K26: CL Trenton
A27: 247 | B27: Transport | C27: (150,144) | D27: Pearl Harbor (180,107) | E27: Pearl Harbor (180,107) | F27: 151,144 > 151,143 > 152,143 > 153,142 > 153,141 | G27: 10 | H27: xAP Nairana | I27: 0.51 | J27: 4 | K27: xAK Dumosa, xAK Kekerangu, xAP Nairana, xAK Cardross, xAK Era, xAK Goulburn, xAK Mernoo, xAK Mundalla, xAK Period, xAK Ulooloo
A28: 248 | B28: Submarine | C28: (52,85) Tandjoengpinang | D28: Colombo (29,48) | F28: 52,84 > 52,84 > 52,84 > 52,84 > 52,84 | G28: 1 | H28: SS K IX | I28: 0.73 | J28: 0 | K28: SS K IX
A29: 249 | B29: Transport | C29: (36,5) | D29: Aden (20,3) | E29: Aden (20,3) | F29: 37,6 > 38,6 > 38,7 > 39,7 > 40,8 | G29: 5 | H29: xAK Durenda | I29: 1 | J29: 1 | K29: xAK Delawarean, xAK West Cawthon, xAK West Isleta, xAK Birminghan City, xAK Durenda
A30: 252 | B30: Submarine | C30: (84,88) near Dinagat | D30: Darwin (76,124) | F30: 84,87 > 84,87 > 84,87 > 84,87 > 84,87 | G30: 3 | H30: SS Stingray | I30: 0.82 | J30: 0 | K30: SS Perch, SS Pickerel, SS Stingray
A31: 256 | B31: Submarine | C31: (74,123) near Darwin | D31: Darwin (76,124) | F31: 75,124 > 76,124 > 75,120 > 74,121 > 74,122 | G31: 1 | H31: SS S-41 | I31: 0.16 | J31: 1 | K31: SS S-41
A32: 258 | B32: Submarine | C32: (83,90) near Siargao | D32: Darwin (76,124) | F32: 82,89 > 82,89 > 82,89 > 82,89 > 82,89 | G32: 1 | H32: SS Saury | I32: 0.84 | J32: 1 | K32: SS Saury
A33: 267 | B33: Submarine | C33: (83,86) near Dinagat | D33: Darwin (76,124) | F33: 82,86 > 82,86 > 82,86 > 82,86 > 85,88 | G33: 1 | H33: SS S-37 | I33: 0.59 | J33: 1 | K33: SS S-37
A34: 269 | B34: Transport (CS convoy) | C34: (175,150) | D34: near San Diego (225,76) | E34: Sydney (90,167) | F34: 174,151 > 174,152 > 173,153 > 173,154 > 175,149 | G34: 6 | H34: TK Mobilstation | I34: 0.86 | J34: 4 | K34: TK Alfred Clegg, TK Mobilfuel, TK Mobilstation, TK California Standard, TK Pat Doheny, TK Manzanillo
A35: 271 | B35: Escort (?) | C35: (201,92) | D35: (211,55) | E35: (211,55) | F35: 201,91 > 201,90 > 201,89 > 201,88 > 201,87 | G35: 8 | H35: BB West Virginia | I35: 0.47 | J35: 5 | K35: BB West Virginia, BB Arizona, DD Bagley, DD Cassin, DD Downes, KV Quesnel, KV Wetaskiwin, KV Chilliwack
A36: 272 | B36: Submarine | C36: (78,121) | D36: Darwin (76,124) | F36: 78,122 > 77,123 > 76,123 > 76,124 > 79,119 | G36: 1 | H36: SS Sailfish | I36: 0.73 | J36: 1 | K36: SS Sailfish
A37: 273 | B37: Submarine | C37: (78,88) near Cagayan | D37: Darwin (76,124) | F37: 79,88 > 79,88 > 79,88 > 79,88 > 79,88 | G37: 1 | H37: SS Sargo | I37: 0.84 | J37: 0 | K37: SS Sargo
A38: 274 | B38: Transport (CS convoy) | C38: (56,104) Soerabaja | D38: Soerabaja (56,104) | E38: (49,141) | F38: 56,105 > 57,105 > 58,106 > 57,107 > 57,108 | G38: 2 | H38: TK Merula | I38: 1 | J38: 1 | K38: TK Pan Europa, TK Merula
A39: 279 | B39: Submarine | C39: (82,78) near Polillo | D39: Darwin (76,124) | F39: 81,77 > 81,77 > 81,77 > 81,77 > 81,77 | G39: 1 | H39: SS Permit | I39: 0.8 | J39: 0 | K39: SS Permit
A40: 283 | B40: Surface Combat | C40: (209,92) | D40: San Diego (227,78) | E40: San Diego (227,78) | F40: 210,92 > 210,91 > 211,91 > 212,90 > 213,90 | G40: 6 | H40: DD Conyngham | I40: 0.61 | J40: 4 | K40: DD Case, DD Conyngham, DD Hull, DD Aylwin, DD Allen, DD Chew
...

Sheet Damaged Ships
A1: Ship | B1: Type | C1: Class | D1: Nation | E1: Location | F1: TF | G1: Captain | H1: Crew exp | I1: Fuel | J1: Max fuel | K1: Fuel % | L1: Endurance (nm) | M1: Max speed (kn) | N1: Sys dmg | O1: Float dmg | P1: Float major | Q1: Eng dmg | R1: Eng major | S1: Fire
A2: K XV | B2: SS | C2: KXIV Class | D2: Netherlands | E2: At sea, TF 466 (53,91) Tambelan-eilanden | F2: 466 | G2: Kloppman B. | H2: 38 | I2: 130 | J2: 159 | K2: 0.81761006 | L2: 8176 | M2: 17 | N2: 65 | O2: 97 | P2: 20 | Q2: 8 | R2: 2 | S2: 0
A3: Java | B3: CL | C3: Java | D3: Netherlands | E3: At sea, TF 339 (63,99) near Balikpapan | F3: 339 | G3: Vanderhorst E. | H3: 61 | I3: 1200 | J3: 1200 | K3: 1 | L3: 3500 | M3: 31 | N3: 60 | O3: 70 | P3: 30 | Q3: 31 | R3: 7 | S3: 0
A4: California | B4: BB | C4: Tennessee | D4: USA | E4: In port: Pearl Harbor (180,107) | G4: McGuire, Q. | H4: 60 | I4: 4700 | J4: 4900 | K4: 0.95918367 | L4: 9900 | M4: 21 | N4: 27 | O4: 71 | P4: 71 | Q4: 29 | R4: 25 | S4: 0
A5: Tennessee | B5: BB | C5: Tennessee | D5: USA | E5: In port: Pearl Harbor (180,107) | G5: Kennedy, C.B. | H5: 58 | I5: 4700 | J5: 4900 | K5: 0.95918367 | L5: 9900 | M5: 21 | N5: 30 | O5: 70 | P5: 70 | Q5: 19 | R5: 9 | S5: 0
A6: Stuart | B6: DD | C6: Admiralty 'Leader' | D6: Australia | E6: In port: Melbourne (82,170) | G6: Levy, K.M. | H6: 61 | I6: 500 | J6: 500 | K6: 1 | L6: 6250 | M6: 36 | N6: 98 | O6: 0 | P6: 0 | Q6: 90 | R6: 90 | S6: 0
A7: Voyager | B7: DD | C7: Admiralty 'W' | D7: Australia | E7: In port: Sydney (90,167) | G7: Blackwell B. | H7: 62 | I7: 367 | J7: 367 | K7: 1 | L7: 3000 | M7: 34 | N7: 99 | O7: 0 | P7: 0 | Q7: 81 | R7: 81 | S7: 0
A8: West Virginia | B8: BB | C8: West Virginia | D8: USA | E8: At sea, TF 271 (201,92) | F8: 271 | G8: Borowski, W.R. | H8: 53 | I8: 2554 | J8: 5400 | K8: 0.47296296 | L8: 5060 | M8: 21 | N8: 57 | O8: 58 | P8: 44 | Q8: 2 | R8: 0 | S8: 0
A9: Sicard | B9: DM | C9: Clemson DM | D9: USA | E9: In port: Pearl Harbor (180,107) | G9: Fultz, H.L. | H9: 46 | I9: 429 | J9: 435 | K9: 0.9862069 | L9: 5225 | M9: 30 | N9: 86 | O9: 0 | P9: 0 | Q9: 88 | R9: 88 | S9: 0
A10: S-27 | B10: SS | C10: Electric Boat S-18 | D10: USA | E10: In port: Mare Island (218,69) | G10: Jukes, H.L. | H10: 53 | I10: 70 | J10: 70 | K10: 1 | L10: 4050 | M10: 14 | N10: 90 | O10: 0 | P10: 0 | Q10: 71 | R10: 71 | S10: 0
A11: S-28 | B11: SS | C11: Electric Boat S-18 | D11: USA | E11: In port: Mare Island (218,69) | G11: Keene R. | H11: 50 | I11: 70 | J11: 70 | K11: 1 | L11: 4050 | M11: 14 | N11: 90 | O11: 0 | P11: 0 | Q11: 71 | R11: 71 | S11: 0
A12: Capetown | B12: CL | C12: 'C' Class | D12: UK | E12: In port: Bombay (36,24) | G12: Greenwood G. | H12: 73 | I12: 935 | J12: 935 | K12: 1 | L12: 6000 | M12: 29 | N12: 50 | O12: 51 | P12: 51 | Q12: 0 | R12: 0 | S12: 0
A13: Duntroon | B13: xAP | C13: Shire | D13: Australia | E13: At sea, TF 510 (166,159) | F13: 510 | G13: Blackwell W. | H13: 15 | I13: 1241 | J13: 2700 | K13: 0.45962963 | L13: 8273 | M13: 18 | N13: 43 | O13: 34 | P13: 14 | Q13: 12 | R13: 0 | S13: 12
A14: Concord | B14: CL | C14: Omaha | D14: USA | E14: In port: San Diego (227,78) | G14: Birkenbach, R.A. | H14: 55 | I14: 1200 | J14: 1200 | K14: 1 | L14: 9000 | M14: 34 | N14: 75 | O14: 0 | P14: 0 | Q14: 43 | R14: 43 | S14: 0
A15: Limerick | B15: xAP | C15: Dominion Troop | D15: New Zealand | E15: At sea, TF 510 (166,159) | F15: 510 | G15: Usher O. | H15: 17 | I15: 789 | J15: 1505 | K15: 0.52425249 | L15: 7654 | M15: 13 | N15: 45 | O15: 19 | P15: 7 | Q15: 15 | R15: 0 | S15: 14
A16: Nevada | B16: BB | C16: Nevada | D16: USA | E16: At sea, TF 230 (216,70) near San Francisco | F16: 230 | G16: Headrick, O.N. | H16: 55 | I16: 1606 | J16: 3150 | K16: 0.50984127 | L16: 3517 | M16: 21 | N16: 32 | O16: 21 | P16: 21 | Q16: 37 | R16: 29 | S16: 0
A17: Oklahoma | B17: BB | C17: Nevada | D17: USA | E17: At sea, TF 230 (216,70) near San Francisco | F17: 230 | G17: Withers, M.C. | H17: 54 | I17: 1606 | J17: 3150 | K17: 0.50984127 | L17: 3517 | M17: 21 | N17: 42 | O17: 32 | P17: 30 | Q17: 5 | R17: 4 | S17: 0
A18: Repulse | B18: BC | C18: Repulse | D18: UK | E18: At sea, TF 219 (45,106) | F18: 219 | G18: Tennant, W.G. | H18: 74 | I18: 2737 | J18: 3525 | K18: 0.7764539 | L18: 6067 | M18: 28 | N18: 32 | O18: 35 | P18: 35 | Q18: 8 | R18: 3 | S18: 0
A19: Tracy | B19: DM | C19: Clemson DM | D19: USA | E19: In port: Pearl Harbor (180,107) | G19: Gehman, C.T. | H19: 42 | I19: 429 | J19: 435 | K19: 0.9862069 | L19: 5225 | M19: 30 | N19: 85 | O19: 0 | P19: 0 | Q19: 24 | R19: 0 | S19: 0
A20: Preble | B20: DM | C20: Clemson DM | D20: USA | E20: In port: Pearl Harbor (180,107) | G20: Sargent, S.E. | H20: 40 | I20: 429 | J20: 435 | K20: 0.9862069 | L20: 5225 | M20: 30 | N20: 84 | O20: 0 | P20: 0 | Q20: 24 | R20: 0 | S20: 0
A21: Prince of Wales | B21: BB | C21: King George V | D21: UK | E21: At sea, TF 314 (5,102) | F21: 314 | G21: Leach, J.C. | H21: 71 | I21: 2570 | J21: 3850 | K21: 0.66753247 | L21: 4939 | M21: 28 | N21: 10 | O21: 40 | P21: 40 | Q21: 14 | R21: 14 | S21: 0
A22: Arizona | B22: BB | C22: Pennsylvania | D22: USA | E22: At sea, TF 271 (201,92) | F22: 271 | G22: Gruenther, K.S. | H22: 53 | I22: 2116 | J22: 3700 | K22: 0.57189189 | L22: 4632 | M22: 21 | N22: 40 | O22: 22 | P22: 19 | Q22: 14 | R22: 13 | S22: 0
A23: Pruitt | B23: DM | C23: Clemson DM | D23: USA | E23: In port: Pearl Harbor (180,107) | G23: Fenoglia, H. | H23: 50 | I23: 429 | J23: 435 | K23: 0.9862069 | L23: 5225 | M23: 30 | N23: 80 | O23: 0 | P23: 0 | Q23: 7 | R23: 0 | S23: 0
A24: St. Louis | B24: CL | C24: Helena | D24: USA | E24: In port: Mare Island (218,69) | G24: Rood, G. | H24: 56 | I24: 1285 | J24: 1982 | K24: 0.64833502 | L24: 9400 | M24: 32 | N24: 17 | O24: 22 | P24: 22 | Q24: 25 | R24: 25 | S24: 0
A25: Boise | B25: CL | C25: Brooklyn | D25: USA | E25: At sea, TF 300 (63,99) near Balikpapan | F25: 300 | G25: Farley R. | H25: 55 | I25: 1001 | J25: 1982 | K25: 0.50504541 | L25: 7323 | M25: 32 | N25: 24 | O25: 22 | P25: 7 | Q25: 18 | R25: 3 | S25: 0
A26: K VIII | B26: SS | C26: KVIII Class | D26: Netherlands | E26: At sea, TF 459 (52,100) near Bandoeng | F26: 459 | G26: Caspers, J.W. | H26: 58 | I26: 75 | J26: 77 | K26: 0.97402597 | L26: 4821 | M26: 16 | N26: 42 | O26: 15 | P26: 10 | Q26: 2 | R26: 0 | S26: 0
A27: Evertsen | B27: DD | C27: Admiralen Batch I | D27: Netherlands | E27: At sea, TF 300 (63,99) near Balikpapan | F27: 300 | G27: de Vries, W.M. | H27: 57 | I27: 224 | J27: 300 | K27: 0.74666667 | L27: 1866 | M27: 36 | N27: 51 | O27: 5 | P27: 5 | Q27: 11 | R27: 2 | S27: 0
A28: K XI | B28: SS | C28: KXI Class | D28: Netherlands | E28: At sea, TF 461 (34,62) | F28: 461 | G28: Cuyler U. | H28: 56 | I28: 35 | J28: 73 | K28: 0.47945205 | L28: 2301 | M28: 17 | N28: 31 | O28: 20 | P28: 20 | Q28: 0 | R28: 0 | S28: 0
A29: Helena | B29: CL | C29: Helena | D29: USA | E29: In port: near Bremerton (212,52) | G29: Hoover, G. | H29: 58 | I29: 1982 | J29: 1982 | K29: 1 | L29: 14500 | M29: 32 | N29: 13 | O29: 25 | P29: 25 | Q29: 1 | R29: 0 | S29: 0
A30: Shinai | B30: xAKL | C30: Pacific S Cargo | D30: UK | E30: At sea, TF 43 (58,117) | F30: 43 | G30: Woodroffe H. | H30: 15 | I30: 125 | J30: 285 | K30: 0.43859649 | L30: 1754 | M30: 10 | N30: 13 | O30: 24 | P30: 7 | Q30: 0 | R30: 0 | S30: 0
A31: Worden | B31: DD | C31: Farragut | D31: USA | E31: In port: near Bremerton (212,52) | G31: Pogue, W. | H31: 60 | I31: 600 | J31: 600 | K31: 1 | L31: 5750 | M31: 32 | N31: 29 | O31: 8 | P31: 8 | Q31: 15 | R31: 9 | S31: 0
A32: Colorado | B32: BB | C32: Colorado | D32: USA | E32: In port: Bremerton (211,52) | G32: D'Alessio, K.E. | H32: 54 | I32: 4700 | J32: 5400 | K32: 0.87037037 | L32: 10700 | M32: 21 | N32: 39 | O32: 0 | P32: 0 | Q32: 20 | R32: 20 | S32: 0
A33: Tautog | B33: SS | C33: Tambor | D33: USA | E33: In port: Pearl Harbor (180,107) | G33: Willingham, J.H. | H33: 59 | I33: 315 | J33: 315 | K33: 1 | L33: 11000 | M33: 20 | N33: 19 | O33: 16 | P33: 16 | Q33: 6 | R33: 6 | S33: 0
A34: K XIII | B34: SS | C34: KXI Class | D34: Netherlands | E34: At sea, TF 463 (53,80) near Terempa | F34: 463 | G34: Van Den Heuvel W. | H34: 59 | I34: 47 | J34: 73 | K34: 0.64383562 | L34: 3090 | M34: 17 | N34: 27 | O34: 13 | P34: 5 | Q34: 2 | R34: 0 | S34: 0
A35: Mauritius | B35: CL | C35: Fiji | D35: UK | E35: At sea, TF 313 (48,132) | F35: 313 | G35: Stephens, W.D. | H35: 69 | I35: 1236 | J35: 1700 | K35: 0.72705882 | L35: 7997 | M35: 31 | N35: 43 | O35: 0 | P35: 0 | Q35: 0 | R35: 0 | S35: 0
A36: MTB 9 | B36: MTB | C36: BPB 60' MTB | D36: UK | E36: At sea, TF 321 (70,123) | F36: 321 | G36: Trenchard H. | H36: 56 | I36: 12 | J36: 20 | K36: 0.6 | L36: 360 | M36: 33 | N36: 37 | O36: 0 | P36: 0 | Q36: 6 | R36: 2 | S36: 0
A37: Tarpon | B37: SS | C37: Shark | D37: USA | E37: At sea, TF 234 (99,121) | F37: 234 | G37: Wallace, L. | H37: 55 | I37: 191 | J37: 295 | K37: 0.64745763 | L37: 7122 | M37: 19 | N37: 29 | O37: 2 | P37: 0 | Q37: 2 | R37: 0 | S37: 0
A38: Sumatra | B38: CL | C38: Java | D38: Netherlands | E38: In port: Colombo (29,48) | G38: Willinge, J.J.L. | H38: 55 | I38: 1200 | J38: 1200 | K38: 1 | L38: 3500 | M38: 31 | N38: 16 | O38: 0 | P38: 0 | Q38: 17 | R38: 17 | S38: 0
A39: Hanyang | B39: xAK | C39: Pacific M Cargo | D39: UK | E39: At sea, TF 299 (73,122) near Darwin | F39: 299 | G39: Drake B. | H39: 28 | I39: 366 | J39: 447 | K39: 0.81879195 | L39: 4912 | M39: 12 | N39: 24 | O39: 0 | P39: 0 | Q39: 0 | R39: 0 | S39: 0
A40: Peisander | B40: xAK | C40: Dominion L Cargo | D40: UK | E40: At sea, TF 510 (166,159) | F40: 510 | G40: Hackett U. | H40: 24 | I40: 880 | J40: 1700 | K40: 0.51764706 | L40: 8696 | M40: 12 | N40: 12 | O40: 2 | P40: 0 | Q40: 6 | R40: 0 | S40: 0
...

Sheet Losses
A1: Ship | B1: Type | C1: Class | D1: Nation | E1: Lost | F1: Last captain
A2: Manoora | B2: AMC | C2: Manoora AMC | D2: Australia | E2: on or before 17 Dec
A3: Platte | B3: AO | C3: Neosho | D3: USA | E3: on or before 17 Dec | F3: Henkle, R.
A4: William B. Preston | B4: AVD | C4: Clemson AVD | D4: USA | E4: on or before 17 Dec
A5: Maryland | B5: BB | C5: Maryland | D5: USA | E5: on or before 17 Dec | F5: Badger, B.W.
A6: Tromp | B6: CL | C6: Tromp | D6: Netherlands | E6: on or before 17 Dec
A7: John D. Ford | B7: DD | C7: Clemson DD | D7: USA | E7: on or before 17 Dec
A8: Pillsbury | B8: DD | C8: Clemson DD | D8: USA | E8: on or before 17 Dec
A9: Pope | B9: DD | C9: Clemson DD | D9: USA | E9: on or before 17 Dec | F9: Musak, F.V.
A10: Kortenaer | B10: DD | C10: Admiralen Batch I | D10: Netherlands | E10: on or before 17 Dec | F10: Kroese, A.
A11: HDML 1062 | B11: HDML | C11: Admiralty HDML | D11: UK | E11: on or before 17 Dec | F11: Sparks T.
A12: HDML 1063 | B12: HDML | C12: Admiralty HDML | D12: UK | E12: on or before 17 Dec | F12: Pringle U.
A13: Pro Patria | B13: ML | C13: Pro Patria | D13: Netherlands | E13: on or before 17 Dec | F13: Haerlen W.
A14: No. 376 | B14: ML | C14: Fairmile B | D14: UK | E14: on or before 17 Dec | F14: Underwood E.
A15: No. 377 | B15: ML | C15: Fairmile B | D15: UK | E15: on or before 17 Dec | F15: Trent F.
A16: Reliance | B16: PC | C16: Active 125' PC | D16: USA | E16: on or before 17 Dec
A17: Governor Wright | B17: xAK | C17: Harriman Cargo | D17: USA | E17: on or before 17 Dec
A18: Bennevis | B18: xAK | C18: Dominion L Cargo | D18: UK | E18: on or before 17 Dec
A19: Demosthenes | B19: xAK | C19: Dominion M Cargo | D19: UK | E19: on or before 17 Dec
A20: Ellenga | B20: xAK | C20: Pacific L Cargo | D20: UK | E20: on or before 17 Dec
A21: Fatshan | B21: xAK | C21: Pacific M Cargo | D21: UK | E21: on or before 17 Dec | F21: Kershaw R.
A22: Indira | B22: xAK | C22: Euro M Cargo | D22: UK | E22: on or before 17 Dec | F22: Peirse N.
A23: Ming Sang | B23: xAK | C23: Pacific L Cargo | D23: UK | E23: on or before 17 Dec | F23: Elster F.
A24: Wing Sang | B24: xAK | C24: Pacific L Cargo | D24: UK | E24: on or before 17 Dec
A25: Lorraine | B25: xAK | C25: Pacific M Cargo | D25: Free French | E25: on or before 17 Dec | F25: Beaufre R.
A26: Somelsdijk | B26: xAK | C26: Euro L Cargo | D26: Netherlands | E26: on or before 17 Dec | F26: Nieuwhuis T.
A27: Toendjoek | B27: xAK | C27: Euro K Cargo | D27: Netherlands | E27: on or before 17 Dec | F27: Balluseck U.
A28: Haraldsvang | B28: xAK | C28: Pacific M Cargo | D28: Other Allied | E28: on or before 17 Dec | F28: Kent U.
A29: Susana | B29: xAKL | C29: Lake Cargo | D29: USA | E29: on or before 17 Dec | F29: Rowan, P.H.
A30: Manini | B30: xAKL | C30: Lake Cargo | D30: USA | E30: on or before 17 Dec
A31: Latouche | B31: xAKL | C31: Coastal Cargo | D31: Philippines | E31: on or before 17 Dec
A32: Legazpi | B32: xAKL | C32: Pacific S Cargo | D32: Philippines | E32: on or before 17 Dec | F32: Echegaray U.
A33: Lepus | B33: xAKL | C33: Coastal Cargo | D33: Philippines | E33: on or before 17 Dec
A34: Surigao | B34: xAKL | C34: Coastal Cargo | D34: Philippines | E34: on or before 17 Dec
A35: Joan Moller | B35: xAKL | C35: Pacific S Cargo | D35: UK | E35: on or before 17 Dec
A36: Lyemun | B36: xAKL | C36: Pacific S Cargo | D36: UK | E36: on or before 17 Dec | F36: Gifford W.
A37: Nam Yong | B37: xAKL | C37: Coastal Cargo | D37: UK | E37: on or before 17 Dec
A38: Yat Shing | B38: xAKL | C38: Pacific S Cargo | D38: UK | E38: on or before 17 Dec
A39: Glenapp | B39: xAP | C39: Empire/Glen | D39: UK | E39: on or before 17 Dec | F39: Caruthers C.
A40: Hong Siang | B40: xAP | C40: Straits/Hong | D40: UK | E40: on or before 17 Dec
...

Sheet Reinforcements
A1: Ship | B1: Type | C1: Class | D1: Nation | E1: Days to arrival | F1: Arrival date | G1: Arrives at
A2: Alchiba | B2: AK | C2: C2 Arcturus | D2: USA | E2: 1 | F2: 1941-12-26 | G2: (227,27)
A3: Strela | B3: AM | C3: Fugas | D3: nation 13 | E3: 1 | F3: 1941-12-26 | G3: near Yenki (112,46)
A4: Cheka | B4: AM | C4: Fugas | D4: nation 13 | E4: 1 | F4: 1941-12-26 | G4: near Yenki (112,46)
A5: Tros | B5: AM | C5: Fugas | D5: nation 13 | E5: 1 | F5: 1941-12-26 | G5: (126,37)
A6: Provodnik | B6: AM | C6: Fugas | D6: nation 13 | E6: 1 | F6: 1941-12-26 | G6: (126,37)
A7: Podsekate | B7: AM | C7: Fugas | D7: nation 13 | E7: 1 | F7: 1941-12-26 | G7: near Yenki (112,46)
A8: Vekha | B8: AM | C8: Fugas | D8: nation 13 | E8: 1 | F8: 1941-12-26 | G8: near Yenki (112,46)
A9: Kapsul | B9: AM | C9: Fugas | D9: nation 13 | E9: 1 | F9: 1941-12-26 | G9: (124,42)
A10: Emerald | B10: CL | C10: 'E' Class 1st Group | D10: UK | E10: 1 | F10: 1941-12-26 | G10: (2,57)
A11: Tbilisi | B11: DD | C11: Leningrad | D11: nation 13 | E11: 1 | F11: 1941-12-26 | G11: near Yenki (112,46)
A12: Ryanyj | B12: DD | C12: Gnevnyi | D12: nation 13 | E12: 1 | F12: 1941-12-26 | G12: near Yenki (112,46)
A13: Rastoropnyj | B13: DD | C13: Gnevnyi | D13: nation 13 | E13: 1 | F13: 1941-12-26 | G13: near Yenki (112,46)
... A364: Uffington Court | B364: xAK | C364: Euro M Cargo | D364: UK | E364: 64 | F364: 1942-02-27 | G364: Aden (20,3)
A365: PT-61 | B365: PT | C365: Elco 77ft PT | D365: USA | E365: 65 | F365: 1942-02-28
A366: Cessnock | B366: AM | C366: Bathurst | D366: Australia | E366: 66 | F366: 1942-03-01 | G366: Sydney (90,167)
A367: Little | B367: APD | C367: Wickes APD | D367: USA | E367: 66 | F367: 1942-03-01 | G367: near Bremerton (211,53)
A368: Ramillies | B368: BB | C368: Royal Sovereign | D368: UK | E368: 66 | F368: 1942-03-01 | G368: Cape Town (2,67)
A369: Arrow | B369: DD | C369: 'A' Class | D369: UK | E369: 66 | F369: 1942-03-01 | G369: Aden (20,3)
A370: Thomas Barry | B370: xAP | C370: Grace Line | D370: USA | E370: 66 | F370: 1942-03-01 | G370: near San Diego (225,76)
A371: Oak | B371: ACM | C371: Alder ACM | D371: USA | E371: 67 | F371: 1942-03-02 | G371: near San Diego (225,76)
A372: Admiral Senn | B372: xAK | C372: Isthmian Cargo | D372: USA | E372: 68 | F372: 1942-03-03 | G372: Cristobal (228,101)
A373: Rodman Coleman | B373: xAK | C373: C2-T Cargo | D373: USA | E373: 68 | F373: 1942-03-03 | G373: Balboa (229,102)
A374: S-44 | B374: SS | C374: Electric Boat S-42 | D374: USA | E374: 69 | F374: 1942-03-04 | G374: San Diego (227,78)
A375: British Confidence | B375: TK | C375: Shell Type-A | D375: UK | E375: 69 | F375: 1942-03-04 | G375: Abadan (39,3)
A376: Benledi | B376: xAK | C376: Dominion M Cargo | D376: UK | E376: 69 | F376: 1942-03-04 | G376: Cape Town (2,67)
A377: Denbighshire | B377: xAP | C377: Empire/Glen | D377: UK | E377: 69 | F377: 1942-03-04 | G377: Cape Town (2,67)
... A421: Atlanta | B421: CLAA | C421: Atlanta | D421: USA | E421: 87 | F421: 1942-03-22 | G421: Balboa (229,102)
A422: PT-59 | B422: PT | C422: Elco 77ft PT | D422: USA | E422: 87 | F422: 1942-03-22
A423: Cornish City | B423: xAK | C423: Euro M Cargo | D423: UK | E423: 87 | F423: 1942-03-22 | G423: Aden (20,3)
A424: Hunter Liggett | B424: AP | C424: Harris | D424: USA | E424: 88 | F424: 1942-03-23 | G424: Balboa (229,102)
A425: No. 372 | B425: ML | C425: Fairmile B | D425: UK | E425: 88 | F425: 1942-03-23 | G425: Singapore (50,84)
A426: No. 365 | B426: ML | C426: Fairmile B | D426: UK | E426: 89 | F426: 1942-03-24 | G426: Singapore (50,84)
A427: YMS-95 | B427: YMS | C427: YMS-1 | D427: USA | E427: 89 | F427: 1942-03-24 | G427: near Alameda (219,69)
A428: Canso | B428: AM | C428: Bangor VTE | D428: Canada | E428: 90 | F428: 1942-03-25 | G428: near Victoria (209,49)
A429: Devonshire | B429: CA | C429: London | D429: UK | E429: 90 | F429: 1942-03-25 | G429: Cape Town (2,67)
A430: PT-60 | B430: PT | C430: Elco 77ft PT | D430: USA | E430: 90 | F430: 1942-03-25
A431: Inconstant | B431: DD | C431: 'I' Class | D431: UK | E431: 91 | F431: 1942-03-26 | G431: Cape Town (2,67)
A432: John Adams | B432: xAK | C432: EC2 Liberty Cargo | D432: USA | E432: 91 | F432: 1942-03-26 | G432: Alameda (219,70)
A433: Punjab | B433: AM | C433: Bathurst | D433: India | E433: 93 | F433: 1942-03-28 | G433: Sydney (90,167)
...

Sheet Notes
A1: How this was decoded
A2: Source: the 25 Dec incoming file, plus the earlier saves for loss dates. Only records with the Allied side flag were read.
A3: Confirmed against the turn reports: ship names, class, type, nation, captain, fuel, endurance, TF membership, TF home/destination, current hex, port, sunk status, arrival countdown.
A4: Inferred, not confirmed: the damage columns. The order is fire, system, float, float (major), engine, engine (major). It matches ships reported hit (e.g. Duntroon on fire, Elisavet torpedoed).
A5: Inferred, not confirmed: 'Crew exp'.
A6: Mission names marked (?) are inferred from what ships the TF contains; unmarked ones were matched to report messages.
A7: Place names come from the turn reports; the save stores bases as coordinates only. 'near X' means within 2 hexes of a named place. Blank = no name found; use the hex coordinates.
A8: Fuel % uses the class maximum from the save's ship-class table.
